[2024-11-15T15:00:24.143+0000] {local_task_job_runner.py:120} INFO - ::group::Pre task execution logs
[2024-11-15T15:00:24.163+0000] {taskinstance.py:2076} INFO - Dependencies all met for dep_context=non-requeueable deps ti=<TaskInstance: download_google_sheet.download_google_sheet_data manual__2024-11-15T15:00:18.511122+00:00 [queued]>
[2024-11-15T15:00:24.175+0000] {taskinstance.py:2076} INFO - Dependencies all met for dep_context=requeueable deps ti=<TaskInstance: download_google_sheet.download_google_sheet_data manual__2024-11-15T15:00:18.511122+00:00 [queued]>
[2024-11-15T15:00:24.175+0000] {taskinstance.py:2306} INFO - Starting attempt 1 of 1
[2024-11-15T15:00:24.190+0000] {taskinstance.py:2330} INFO - Executing <Task(PythonOperator): download_google_sheet_data> on 2024-11-15 15:00:18.511122+00:00
[2024-11-15T15:00:24.196+0000] {warnings.py:110} WARNING - /home/***/.local/lib/python3.12/site-packages/***/task/task_runner/standard_task_runner.py:61: DeprecationWarning: This process (pid=191) is multi-threaded, use of fork() may lead to deadlocks in the child.
  pid = os.fork()

[2024-11-15T15:00:24.201+0000] {standard_task_runner.py:63} INFO - Started process 194 to run task
[2024-11-15T15:00:24.201+0000] {standard_task_runner.py:90} INFO - Running: ['***', 'tasks', 'run', 'download_google_sheet', 'download_google_sheet_data', 'manual__2024-11-15T15:00:18.511122+00:00', '--job-id', '3', '--raw', '--subdir', 'DAGS_FOLDER/etl_sheets_to_postgres.py', '--cfg-path', '/tmp/tmp6zysx7m6']
[2024-11-15T15:00:24.206+0000] {standard_task_runner.py:91} INFO - Job 3: Subtask download_google_sheet_data
[2024-11-15T15:00:24.353+0000] {task_command.py:426} INFO - Running <TaskInstance: download_google_sheet.download_google_sheet_data manual__2024-11-15T15:00:18.511122+00:00 [running]> on host 7f2a459ae460
[2024-11-15T15:00:24.477+0000] {taskinstance.py:2648} INFO - Exporting env vars: AIRFLOW_CTX_DAG_OWNER='***' AIRFLOW_CTX_DAG_ID='download_google_sheet' AIRFLOW_CTX_TASK_ID='download_google_sheet_data' AIRFLOW_CTX_EXECUTION_DATE='2024-11-15T15:00:18.511122+00:00' AIRFLOW_CTX_TRY_NUMBER='1' AIRFLOW_CTX_DAG_RUN_ID='manual__2024-11-15T15:00:18.511122+00:00'
[2024-11-15T15:00:24.479+0000] {taskinstance.py:430} INFO - ::endgroup::
[2024-11-15T15:00:24.542+0000] {taskinstance.py:441} INFO - ::group::Post task execution logs
[2024-11-15T15:00:24.558+0000] {taskinstance.py:2905} ERROR - Task failed with exception
Traceback (most recent call last):
  File "/home/airflow/.local/lib/python3.12/site-packages/airflow/models/taskinstance.py", line 465, in _execute_task
    result = _execute_callable(context=context, **execute_callable_kwargs)
             ^^^^^^^^^^^^^^^^^^^^^^^^^^^^^^^^^^^^^^^^^^^^^^^^^^^^^^^^^^^^^
  File "/home/airflow/.local/lib/python3.12/site-packages/airflow/models/taskinstance.py", line 432, in _execute_callable
    return execute_callable(context=context, **execute_callable_kwargs)
           ^^^^^^^^^^^^^^^^^^^^^^^^^^^^^^^^^^^^^^^^^^^^^^^^^^^^^^^^^^^^
  File "/home/airflow/.local/lib/python3.12/site-packages/airflow/models/baseoperator.py", line 400, in wrapper
    return func(self, *args, **kwargs)
           ^^^^^^^^^^^^^^^^^^^^^^^^^^^
  File "/home/airflow/.local/lib/python3.12/site-packages/airflow/operators/python.py", line 235, in execute
    return_value = self.execute_callable()
                   ^^^^^^^^^^^^^^^^^^^^^^^
  File "/home/airflow/.local/lib/python3.12/site-packages/airflow/operators/python.py", line 252, in execute_callable
    return self.python_callable(*self.op_args, **self.op_kwargs)
           ^^^^^^^^^^^^^^^^^^^^^^^^^^^^^^^^^^^^^^^^^^^^^^^^^^^^^
  File "/opt/airflow/dags/etl_sheets_to_postgres.py", line 15, in download_google_sheet_data
    hook = GSheetsHook(gcp_conn_id='google_sheets_default')  # Connection ID from Airflow
           ^^^^^^^^^^^^^^^^^^^^^^^^^^^^^^^^^^^^^^^^^^^^^^^^
  File "/home/airflow/.local/lib/python3.12/site-packages/airflow/providers/google/suite/hooks/sheets.py", line 58, in __init__
    super().__init__(
  File "/home/airflow/.local/lib/python3.12/site-packages/airflow/providers/google/common/hooks/base_google.py", line 252, in __init__
    self.extras: dict = self.get_connection(self.gcp_conn_id).extra_dejson
                        ^^^^^^^^^^^^^^^^^^^^^^^^^^^^^^^^^^^^^
  File "/home/airflow/.local/lib/python3.12/site-packages/airflow/hooks/base.py", line 83, in get_connection
    conn = Connection.get_connection_from_secrets(conn_id)
           ^^^^^^^^^^^^^^^^^^^^^^^^^^^^^^^^^^^^^^^^^^^^^^^
  File "/home/airflow/.local/lib/python3.12/site-packages/airflow/models/connection.py", line 519, in get_connection_from_secrets
    raise AirflowNotFoundException(f"The conn_id `{conn_id}` isn't defined")
airflow.exceptions.AirflowNotFoundException: The conn_id `google_sheets_default` isn't defined
[2024-11-15T15:00:24.568+0000] {taskinstance.py:1206} INFO - Marking task as FAILED. dag_id=download_google_sheet, task_id=download_google_sheet_data, run_id=manual__2024-11-15T15:00:18.511122+00:00, execution_date=20241115T150018, start_date=20241115T150024, end_date=20241115T150024
[2024-11-15T15:00:24.589+0000] {standard_task_runner.py:110} ERROR - Failed to execute job 3 for task download_google_sheet_data (The conn_id `google_sheets_default` isn't defined; 194)
[2024-11-15T15:00:24.612+0000] {local_task_job_runner.py:240} INFO - Task exited with return code 1
[2024-11-15T15:00:24.630+0000] {taskinstance.py:3498} INFO - 0 downstream tasks scheduled from follow-on schedule check
[2024-11-15T15:00:24.632+0000] {local_task_job_runner.py:222} INFO - ::endgroup::
