[2024-11-15T16:35:58.344+0000] {local_task_job_runner.py:120} INFO - ::group::Pre task execution logs
[2024-11-15T16:35:58.543+0000] {taskinstance.py:2076} INFO - Dependencies all met for dep_context=non-requeueable deps ti=<TaskInstance: FLOAT_DATA_TO_PG.ingest_to_postgres manual__2024-11-15T16:35:51.208162+00:00 [queued]>
[2024-11-15T16:35:58.551+0000] {taskinstance.py:2076} INFO - Dependencies all met for dep_context=requeueable deps ti=<TaskInstance: FLOAT_DATA_TO_PG.ingest_to_postgres manual__2024-11-15T16:35:51.208162+00:00 [queued]>
[2024-11-15T16:35:58.552+0000] {taskinstance.py:2306} INFO - Starting attempt 1 of 1
[2024-11-15T16:35:58.565+0000] {taskinstance.py:2330} INFO - Executing <Task(PythonOperator): ingest_to_postgres> on 2024-11-15 16:35:51.208162+00:00
[2024-11-15T16:35:58.571+0000] {warnings.py:110} WARNING - /home/***/.local/lib/python3.12/site-packages/***/task/task_runner/standard_task_runner.py:61: DeprecationWarning: This process (pid=225) is multi-threaded, use of fork() may lead to deadlocks in the child.
  pid = os.fork()

[2024-11-15T16:35:58.572+0000] {standard_task_runner.py:63} INFO - Started process 227 to run task
[2024-11-15T16:35:58.573+0000] {standard_task_runner.py:90} INFO - Running: ['***', 'tasks', 'run', 'FLOAT_DATA_TO_PG', 'ingest_to_postgres', 'manual__2024-11-15T16:35:51.208162+00:00', '--job-id', '26', '--raw', '--subdir', 'DAGS_FOLDER/etl_process_float_data.py', '--cfg-path', '/tmp/tmpoo3hcyxy']
[2024-11-15T16:35:58.575+0000] {standard_task_runner.py:91} INFO - Job 26: Subtask ingest_to_postgres
[2024-11-15T16:35:58.620+0000] {task_command.py:426} INFO - Running <TaskInstance: FLOAT_DATA_TO_PG.ingest_to_postgres manual__2024-11-15T16:35:51.208162+00:00 [running]> on host 35eb7317174e
[2024-11-15T16:35:58.708+0000] {taskinstance.py:2648} INFO - Exporting env vars: AIRFLOW_CTX_DAG_OWNER='***' AIRFLOW_CTX_DAG_ID='FLOAT_DATA_TO_PG' AIRFLOW_CTX_TASK_ID='ingest_to_postgres' AIRFLOW_CTX_EXECUTION_DATE='2024-11-15T16:35:51.208162+00:00' AIRFLOW_CTX_TRY_NUMBER='1' AIRFLOW_CTX_DAG_RUN_ID='manual__2024-11-15T16:35:51.208162+00:00'
[2024-11-15T16:35:58.709+0000] {taskinstance.py:430} INFO - ::endgroup::
[2024-11-15T16:35:58.743+0000] {base.py:84} INFO - Using connection ID 'postgres' for task execution.
[2024-11-15T16:35:58.744+0000] {taskinstance.py:441} INFO - ::group::Post task execution logs
[2024-11-15T16:35:58.745+0000] {taskinstance.py:2905} ERROR - Task failed with exception
Traceback (most recent call last):
  File "/home/airflow/.local/lib/python3.12/site-packages/airflow/models/taskinstance.py", line 465, in _execute_task
    result = _execute_callable(context=context, **execute_callable_kwargs)
             ^^^^^^^^^^^^^^^^^^^^^^^^^^^^^^^^^^^^^^^^^^^^^^^^^^^^^^^^^^^^^
  File "/home/airflow/.local/lib/python3.12/site-packages/airflow/models/taskinstance.py", line 432, in _execute_callable
    return execute_callable(context=context, **execute_callable_kwargs)
           ^^^^^^^^^^^^^^^^^^^^^^^^^^^^^^^^^^^^^^^^^^^^^^^^^^^^^^^^^^^^
  File "/home/airflow/.local/lib/python3.12/site-packages/airflow/models/baseoperator.py", line 400, in wrapper
    return func(self, *args, **kwargs)
           ^^^^^^^^^^^^^^^^^^^^^^^^^^^
  File "/home/airflow/.local/lib/python3.12/site-packages/airflow/operators/python.py", line 235, in execute
    return_value = self.execute_callable()
                   ^^^^^^^^^^^^^^^^^^^^^^^
  File "/home/airflow/.local/lib/python3.12/site-packages/airflow/operators/python.py", line 252, in execute_callable
    return self.python_callable(*self.op_args, **self.op_kwargs)
           ^^^^^^^^^^^^^^^^^^^^^^^^^^^^^^^^^^^^^^^^^^^^^^^^^^^^^
  File "/opt/airflow/dags/etl_process_float_data.py", line 60, in ingest_to_postgres
    conn = postgres_hook.get_conn()
           ^^^^^^^^^^^^^^^^^^^^^^^^
  File "/home/airflow/.local/lib/python3.12/site-packages/airflow/providers/postgres/hooks/postgres.py", line 161, in get_conn
    self.conn = psycopg2.connect(**conn_args)
                ^^^^^^^^^^^^^^^^^^^^^^^^^^^^^
  File "/home/airflow/.local/lib/python3.12/site-packages/psycopg2/__init__.py", line 122, in connect
    conn = _connect(dsn, connection_factory=connection_factory, **kwasync)
           ^^^^^^^^^^^^^^^^^^^^^^^^^^^^^^^^^^^^^^^^^^^^^^^^^^^^^^^^^^^^^^^
psycopg2.OperationalError: connection to server at "localhost" (::1), port 5432 failed: Connection refused
	Is the server running on that host and accepting TCP/IP connections?
connection to server at "localhost" (127.0.0.1), port 5432 failed: Connection refused
	Is the server running on that host and accepting TCP/IP connections?

[2024-11-15T16:35:58.757+0000] {taskinstance.py:1206} INFO - Marking task as FAILED. dag_id=FLOAT_DATA_TO_PG, task_id=ingest_to_postgres, run_id=manual__2024-11-15T16:35:51.208162+00:00, execution_date=20241115T163551, start_date=20241115T163558, end_date=20241115T163558
[2024-11-15T16:35:58.770+0000] {standard_task_runner.py:110} ERROR - Failed to execute job 26 for task ingest_to_postgres (connection to server at "localhost" (::1), port 5432 failed: Connection refused
	Is the server running on that host and accepting TCP/IP connections?
connection to server at "localhost" (127.0.0.1), port 5432 failed: Connection refused
	Is the server running on that host and accepting TCP/IP connections?
; 227)
[2024-11-15T16:35:58.794+0000] {local_task_job_runner.py:240} INFO - Task exited with return code 1
[2024-11-15T16:35:58.810+0000] {taskinstance.py:3498} INFO - 0 downstream tasks scheduled from follow-on schedule check
[2024-11-15T16:35:58.812+0000] {local_task_job_runner.py:222} INFO - ::endgroup::
